Workbook

Sheet 📋 Problem List
A1: 🎯 DSA Tracker — Two Pointers | Sliding Window | Prefix Sum | SDE-2 Interview Prep
A2: # | B2: Problem Name | C2: LC # | D2: Topic | E2: Sub-topic | F2: Difficulty | G2: Day | H2: Status | I2: Time (min) | J2: Notes / Pattern Key | K2: Link | L2: Review?
A3: 1 | B3: Valid Palindrome | C3: 125 | D3: Two Pointers | E3: Basics | F3: Easy | G3: 1 | H3: Done | K3: =HYPERLINK("https://leetcode.com/problems/valid-palindrome/","🔗 Open") -> 🔗 Open | L3: No
A4: 2 | B4: Reverse String | C4: 344 | D4: Two Pointers | E4: Basics | F4: Easy | G4: 1 | H4: Done | K4: =HYPERLINK("https://leetcode.com/problems/reverse-string/","🔗 Open") -> 🔗 Open | L4: No
A5: 3 | B5: Two Sum II – Sorted Array | C5: 167 | D5: Two Pointers | E5: Basics | F5: Medium | G5: 1 | H5: Done | K5: =HYPERLINK("https://leetcode.com/problems/two-sum-ii-input-array-is-sorted/","🔗 Open") -> 🔗 Open | L5: No
A6: 4 | B6: Remove Duplicates from Sorted Array | C6: 26 | D6: Two Pointers | E6: Same Direction | F6: Easy | G6: 1 | H6: Done | K6: =HYPERLINK("https://leetcode.com/problems/remove-duplicates-from-sorted-array/","🔗 Open") -> 🔗 Open | L6: No
A7: 5 | B7: Move Zeroes | C7: 283 | D7: Two Pointers | E7: Same Direction | F7: Easy | G7: 1 | H7: Done | K7: =HYPERLINK("https://leetcode.com/problems/move-zeroes/","🔗 Open") -> 🔗 Open | L7: No
A8: 6 | B8: Container With Most Water | C8: 11 | D8: Two Pointers | E8: Opposite Ends | F8: Medium | G8: 2 | H8: To Do | K8: =HYPERLINK("https://leetcode.com/problems/container-with-most-water/","🔗 Open") -> 🔗 Open | L8: No
A9: 7 | B9: Linked List Cycle | C9: 141 | D9: Two Pointers | E9: Fast & Slow | F9: Easy | G9: 2 | H9: To Do | K9: =HYPERLINK("https://leetcode.com/problems/linked-list-cycle/","🔗 Open") -> 🔗 Open | L9: No
A10: 8 | B10: 3Sum | C10: 15 | D10: Two Pointers | E10: Opposite Ends | F10: Medium | G10: 2 | H10: To Do | K10: =HYPERLINK("https://leetcode.com/problems/3sum/","🔗 Open") -> 🔗 Open | L10: No
A11: 9 | B11: Sort Colors (Dutch Flag) | C11: 75 | D11: Two Pointers | E11: 3-Way Partition | F11: Medium | G11: 2 | H11: To Do | K11: =HYPERLINK("https://leetcode.com/problems/sort-colors/","🔗 Open") -> 🔗 Open | L11: No
A12: 10 | B12: Boats to Save People | C12: 881 | D12: Two Pointers | E12: Opposite Ends | F12: Medium | G12: 2 | H12: To Do | K12: =HYPERLINK("https://leetcode.com/problems/boats-to-save-people/","🔗 Open") -> 🔗 Open | L12: No
A13: 11 | B13: 4Sum | C13: 18 | D13: Two Pointers | E13: Opposite Ends | F13: Medium | G13: 3 | H13: To Do | K13: =HYPERLINK("https://leetcode.com/problems/4sum/","🔗 Open") -> 🔗 Open | L13: No
A14: 12 | B14: Trapping Rain Water | C14: 42 | D14: Two Pointers | E14: Hard Classic | F14: Hard | G14: 3 | H14: To Do | K14: =HYPERLINK("https://leetcode.com/problems/trapping-rain-water/","🔗 Open") -> 🔗 Open | L14: No
A15: 13 | B15: Partition Labels | C15: 763 | D15: Two Pointers | E15: Greedy + TP | F15: Medium | G15: 3 | H15: To Do | K15: =HYPERLINK("https://leetcode.com/problems/partition-labels/","🔗 Open") -> 🔗 Open | L15: No
A16: 14 | B16: Squares of a Sorted Array | C16: 977 | D16: Two Pointers | E16: Opposite Ends | F16: Easy | G16: 3 | H16: To Do | K16: =HYPERLINK("https://leetcode.com/problems/squares-of-a-sorted-array/","🔗 Open") -> 🔗 Open | L16: No
A17: 15 | B17: Running Sum of 1D Array | C17: 1480 | D17: Prefix Sum | E17: Basics | F17: Easy | G17: 4 | H17: To Do | K17: =HYPERLINK("https://leetcode.com/problems/running-sum-of-1d-array/","🔗 Open") -> 🔗 Open | L17: No
A18: 16 | B18: Find Pivot Index | C18: 724 | D18: Prefix Sum | E18: Basics | F18: Easy | G18: 4 | H18: To Do | K18: =HYPERLINK("https://leetcode.com/problems/find-pivot-index/","🔗 Open") -> 🔗 Open | L18: No
A19: 17 | B19: Range Sum Query – Immutable | C19: 303 | D19: Prefix Sum | E19: Basics | F19: Easy | G19: 4 | H19: To Do | K19: =HYPERLINK("https://leetcode.com/problems/range-sum-query-immutable/","🔗 Open") -> 🔗 Open | L19: No
A20: 18 | B20: Product of Array Except Self | C20: 238 | D20: Prefix Sum | E20: Prefix+Suffix | F20: Medium | G20: 4 | H20: To Do | K20: =HYPERLINK("https://leetcode.com/problems/product-of-array-except-self/","🔗 Open") -> 🔗 Open | L20: No
A21: 19 | B21: Subarray Sum Equals K | C21: 560 | D21: Prefix Sum | E21: HashMap | F21: Medium | G21: 4 | H21: To Do | K21: =HYPERLINK("https://leetcode.com/problems/subarray-sum-equals-k/","🔗 Open") -> 🔗 Open | L21: No
A22: 20 | B22: Continuous Subarray Sum | C22: 523 | D22: Prefix Sum | E22: HashMap + Mod | F22: Medium | G22: 5 | H22: To Do | K22: =HYPERLINK("https://leetcode.com/problems/continuous-subarray-sum/","🔗 Open") -> 🔗 Open | L22: No
A23: 21 | B23: Subarray Sums Divisible by K | C23: 974 | D23: Prefix Sum | E23: HashMap + Mod | F23: Medium | G23: 5 | H23: To Do | K23: =HYPERLINK("https://leetcode.com/problems/subarray-sums-divisible-by-k/","🔗 Open") -> 🔗 Open | L23: No
A24: 22 | B24: Longest Subarray With Sum K | C24: GFG | D24: Prefix Sum | E24: HashMap | F24: Medium | G24: 5 | H24: To Do | K24: =HYPERLINK("https://practice.geeksforgeeks.org/problems/longest-sub-array-with-sum-k0809/1","🔗 Open") -> 🔗 Open | L24: No
A25: 23 | B25: Matrix Block Sum | C25: 1314 | D25: Prefix Sum | E25: 2D Prefix | F25: Medium | G25: 5 | H25: To Do | K25: =HYPERLINK("https://leetcode.com/problems/matrix-block-sum/","🔗 Open") -> 🔗 Open | L25: No
A26: 24 | B26: Range Addition | C26: 370 | D26: Prefix Sum | E26: Difference Array | F26: Medium | G26: 5 | H26: To Do | K26: =HYPERLINK("https://leetcode.com/problems/range-addition/","🔗 Open") -> 🔗 Open | L26: No
A27: 25 | B27: Max Sum Subarray of Size K | C27: GFG | D27: Sliding Window | E27: Fixed | F27: Easy | G27: 6 | H27: To Do | K27: =HYPERLINK("https://practice.geeksforgeeks.org/problems/max-sum-subarray-of-size-k5313/1","🔗 Open") -> 🔗 Open | L27: No
A28: 26 | B28: First Negative in Every Window | C28: GFG | D28: Sliding Window | E28: Fixed | F28: Medium | G28: 6 | H28: To Do | K28: =HYPERLINK("https://practice.geeksforgeeks.org/problems/first-negative-in-every-window-of-size-k3345/1","🔗 Open") -> 🔗 Open | L28: No
A29: 27 | B29: Maximum Average Subarray I | C29: 643 | D29: Sliding Window | E29: Fixed | F29: Easy | G29: 6 | H29: To Do | K29: =HYPERLINK("https://leetcode.com/problems/maximum-average-subarray-i/","🔗 Open") -> 🔗 Open | L29: No
A30: 28 | B30: Longest Substring Without Repeating | C30: 3 | D30: Sliding Window | E30: Dynamic | F30: Medium | G30: 6 | H30: To Do | K30: =HYPERLINK("https://leetcode.com/problems/longest-substring-without-repeating-characters/","🔗 Open") -> 🔗 Open | L30: No
A31: 29 | B31: Minimum Size Subarray Sum | C31: 209 | D31: Sliding Window | E31: Dynamic | F31: Medium | G31: 6 | H31: To Do | K31: =HYPERLINK("https://leetcode.com/problems/minimum-size-subarray-sum/","🔗 Open") -> 🔗 Open | L31: No
A32: 30 | B32: Fruit Into Baskets | C32: 904 | D32: Sliding Window | E32: Dynamic | F32: Medium | G32: 6 | H32: To Do | K32: =HYPERLINK("https://leetcode.com/problems/fruit-into-baskets/","🔗 Open") -> 🔗 Open | L32: No
A33: 31 | B33: Permutation in String | C33: 567 | D33: Sliding Window | E33: Freq Map Fixed | F33: Medium | G33: 7 | H33: To Do | K33: =HYPERLINK("https://leetcode.com/problems/permutation-in-string/","🔗 Open") -> 🔗 Open | L33: No
A34: 32 | B34: Find All Anagrams in a String | C34: 438 | D34: Sliding Window | E34: Freq Map Fixed | F34: Medium | G34: 7 | H34: To Do | K34: =HYPERLINK("https://leetcode.com/problems/find-all-anagrams-in-a-string/","🔗 Open") -> 🔗 Open | L34: No
A35: 33 | B35: Longest Substring At Most K Distinct | C35: 340 | D35: Sliding Window | E35: Freq Map Dyn | F35: Medium | G35: 7 | H35: To Do | K35: =HYPERLINK("https://leetcode.com/problems/longest-substring-with-at-most-k-distinct-characters/","🔗 Open") -> 🔗 Open | L35: No
A36: 34 | B36: Longest Repeating Char Replacement | C36: 424 | D36: Sliding Window | E36: Freq Map Dyn | F36: Medium | G36: 7 | H36: To Do | K36: =HYPERLINK("https://leetcode.com/problems/longest-repeating-character-replacement/","🔗 Open") -> 🔗 Open | L36: No
A37: 35 | B37: Max Consecutive Ones III | C37: 1004 | D37: Sliding Window | E37: Dynamic | F37: Medium | G37: 7 | H37: To Do | K37: =HYPERLINK("https://leetcode.com/problems/max-consecutive-ones-iii/","🔗 Open") -> 🔗 Open | L37: No
A38: 36 | B38: Minimum Window Substring | C38: 76 | D38: Sliding Window | E38: Hard | F38: Hard | G38: 7 | H38: To Do | K38: =HYPERLINK("https://leetcode.com/problems/minimum-window-substring/","🔗 Open") -> 🔗 Open | L38: No
A39: 37 | B39: Sliding Window Maximum | C39: 239 | D39: Sliding Window | E39: Deque | F39: Hard | G39: 7 | H39: To Do | K39: =HYPERLINK("https://leetcode.com/problems/sliding-window-maximum/","🔗 Open") -> 🔗 Open | L39: No

Sheet 📅 Day Plan
A1: 📅 7-Day Study Plan + 2 Buffer Days | ~4-5 Problems/Day | Total: 37 Problems
A2: Day | B2: Focus / Tip | C2: LC # | D2: Src | E2: Difficulty | F2: ✅ | G2: Problem (click to open) | H2: Est. Time
A3: DAY 1 | B3: Two Pointers — Basics 💡 Build left-right intuition. Nail same-direction pointer for in-place ops. | C3: 125 | D3: LC | E3: Easy | F3: ✅ | G3: =HYPERLINK("https://leetcode.com/problems/valid-palindrome/","Valid Palindrome") -> Valid Palindrome | H3: 15–20 min
C4: 344 | D4: LC | E4: Easy | F4: ✅ | G4: =HYPERLINK("https://leetcode.com/problems/reverse-string/","Reverse String") -> Reverse String | H4: 15–20 min
C5: 167 | D5: LC | E5: Medium | F5: ✅ | G5: =HYPERLINK("https://leetcode.com/problems/two-sum-ii-input-array-is-sorted/","Two Sum II – Sorted Array") -> Two Sum II – Sorted Array | H5: 25–35 min
C6: 26 | D6: LC | E6: Easy | F6: ✅ | G6: =HYPERLINK("https://leetcode.com/problems/remove-duplicates-from-sorted-array/","Remove Duplicates from Sorted Array") -> Remove Duplicates from Sorted Array | H6: 15–20 min
C7: 283 | D7: LC | E7: Easy | F7: ✅ | G7: =HYPERLINK("https://leetcode.com/problems/move-zeroes/","Move Zeroes") -> Move Zeroes | H7: 15–20 min
A9: DAY 2 | B9: Two Pointers — Classic Medium 💡 3Sum is the most repeated interview problem. Master skip-duplicates logic. | C9: 11 | D9: LC | E9: Medium | F9: ☐ | G9: =HYPERLINK("https://leetcode.com/problems/container-with-most-water/","Container With Most Water") -> Container With Most Water | H9: 25–35 min
C10: 141 | D10: LC | E10: Easy | F10: ☐ | G10: =HYPERLINK("https://leetcode.com/problems/linked-list-cycle/","Linked List Cycle") -> Linked List Cycle | H10: 15–20 min
C11: 15 | D11: LC | E11: Medium | F11: ☐ | G11: =HYPERLINK("https://leetcode.com/problems/3sum/","3Sum") -> 3Sum | H11: 25–35 min
C12: 75 | D12: LC | E12: Medium | F12: ☐ | G12: =HYPERLINK("https://leetcode.com/problems/sort-colors/","Sort Colors (Dutch Flag)") -> Sort Colors (Dutch Flag) | H12: 25–35 min
C13: 881 | D13: LC | E13: Medium | F13: ☐ | G13: =HYPERLINK("https://leetcode.com/problems/boats-to-save-people/","Boats to Save People") -> Boats to Save People | H13: 25–35 min
A15: DAY 3 | B15: Two Pointers — Hard + Greedy 💡 Trapping Rain Water = #1 Google/Meta problem. Understand two-wall logic. | C15: 18 | D15: LC | E15: Medium | F15: ☐ | G15: =HYPERLINK("https://leetcode.com/problems/4sum/","4Sum") -> 4Sum | H15: 25–35 min
C16: 42 | D16: LC | E16: Hard | F16: ☐ | G16: =HYPERLINK("https://leetcode.com/problems/trapping-rain-water/","Trapping Rain Water") -> Trapping Rain Water | H16: 40–55 min
C17: 763 | D17: LC | E17: Medium | F17: ☐ | G17: =HYPERLINK("https://leetcode.com/problems/partition-labels/","Partition Labels") -> Partition Labels | H17: 25–35 min
C18: 977 | D18: LC | E18: Easy | F18: ☐ | G18: =HYPERLINK("https://leetcode.com/problems/squares-of-a-sorted-array/","Squares of a Sorted Array") -> Squares of a Sorted Array | H18: 15–20 min
A20: DAY 4 | B20: Prefix Sum — Basics + Tricks 💡 Product of Array Except Self is a killer trick — must know for top MNCs. | C20: 1480 | D20: LC | E20: Easy | F20: ☐ | G20: =HYPERLINK("https://leetcode.com/problems/running-sum-of-1d-array/","Running Sum of 1D Array") -> Running Sum of 1D Array | H20: 15–20 min
C21: 724 | D21: LC | E21: Easy | F21: ☐ | G21: =HYPERLINK("https://leetcode.com/problems/find-pivot-index/","Find Pivot Index") -> Find Pivot Index | H21: 15–20 min
C22: 303 | D22: LC | E22: Easy | F22: ☐ | G22: =HYPERLINK("https://leetcode.com/problems/range-sum-query-immutable/","Range Sum Query – Immutable") -> Range Sum Query – Immutable | H22: 15–20 min
C23: 238 | D23: LC | E23: Medium | F23: ☐ | G23: =HYPERLINK("https://leetcode.com/problems/product-of-array-except-self/","Product of Array Except Self") -> Product of Array Except Self | H23: 25–35 min
C24: 560 | D24: LC | E24: Medium | F24: ☐ | G24: =HYPERLINK("https://leetcode.com/problems/subarray-sum-equals-k/","Subarray Sum Equals K") -> Subarray Sum Equals K | H24: 25–35 min
A26: DAY 5 | B26: Prefix Sum — HashMap & 2D 💡 Prefix+mod trick covers 3+ common interview problems. Difference array too. | C26: 523 | D26: LC | E26: Medium | F26: ☐ | G26: =HYPERLINK("https://leetcode.com/problems/continuous-subarray-sum/","Continuous Subarray Sum") -> Continuous Subarray Sum | H26: 25–35 min
C27: 974 | D27: LC | E27: Medium | F27: ☐ | G27: =HYPERLINK("https://leetcode.com/problems/subarray-sums-divisible-by-k/","Subarray Sums Divisible by K") -> Subarray Sums Divisible by K | H27: 25–35 min
C28: GFG | D28: GFG | E28: Medium | F28: ☐ | G28: =HYPERLINK("https://practice.geeksforgeeks.org/problems/longest-sub-array-with-sum-k0809/1","Longest Subarray With Sum K") -> Longest Subarray With Sum K | H28: 25–35 min
C29: 1314 | D29: LC | E29: Medium | F29: ☐ | G29: =HYPERLINK("https://leetcode.com/problems/matrix-block-sum/","Matrix Block Sum") -> Matrix Block Sum | H29: 25–35 min
C30: 370 | D30: LC | E30: Medium | F30: ☐ | G30: =HYPERLINK("https://leetcode.com/problems/range-addition/","Range Addition") -> Range Addition | H30: 25–35 min
A32: DAY 6 | B32: Sliding Window — Fixed + Dynamic 💡 Master shrink/expand pattern. Fruit Into Baskets = at most K distinct keys. | C32: GFG | D32: GFG | E32: Easy | F32: ☐ | G32: =HYPERLINK("https://practice.geeksforgeeks.org/problems/max-sum-subarray-of-size-k5313/1","Max Sum Subarray of Size K") -> Max Sum Subarray of Size K | H32: 15–20 min
C33: GFG | D33: GFG | E33: Medium | F33: ☐ | G33: =HYPERLINK("https://practice.geeksforgeeks.org/problems/first-negative-in-every-window-of-size-k3345/1","First Negative in Every Window") -> First Negative in Every Window | H33: 25–35 min
C34: 643 | D34: LC | E34: Easy | F34: ☐ | G34: =HYPERLINK("https://leetcode.com/problems/maximum-average-subarray-i/","Maximum Average Subarray I") -> Maximum Average Subarray I | H34: 15–20 min
C35: 3 | D35: LC | E35: Medium | F35: ☐ | G35: =HYPERLINK("https://leetcode.com/problems/longest-substring-without-repeating-characters/","Longest Substring Without Repeating") -> Longest Substring Without Repeating | H35: 25–35 min
C36: 209 | D36: LC | E36: Medium | F36: ☐ | G36: =HYPERLINK("https://leetcode.com/problems/minimum-size-subarray-sum/","Minimum Size Subarray Sum") -> Minimum Size Subarray Sum | H36: 25–35 min
C37: 904 | D37: LC | E37: Medium | F37: ☐ | G37: =HYPERLINK("https://leetcode.com/problems/fruit-into-baskets/","Fruit Into Baskets") -> Fruit Into Baskets | H37: 25–35 min
A39: DAY 7 | B39: Sliding Window — Freq Map + Hard 💡 Anagram pattern + deque for max window. Minimum Window Substring = top 10 interview. | C39: 567 | D39: LC | E39: Medium | F39: ☐ | G39: =HYPERLINK("https://leetcode.com/problems/permutation-in-string/","Permutation in String") -> Permutation in String | H39: 25–35 min
C40: 438 | D40: LC | E40: Medium | F40: ☐ | G40: =HYPERLINK("https://leetcode.com/problems/find-all-anagrams-in-a-string/","Find All Anagrams in a String") -> Find All Anagrams in a String | H40: 25–35 min
C41: 340 | D41: LC | E41: Medium | F41: ☐ | G41: =HYPERLINK("https://leetcode.com/problems/longest-substring-with-at-most-k-distinct-characters/","Longest Substring At Most K Distinct") -> Longest Substring At Most K Distinct | H41: 25–35 min
C42: 424 | D42: LC | E42: Medium | F42: ☐ | G42: =HYPERLINK("https://leetcode.com/problems/longest-repeating-character-replacement/","Longest Repeating Char Replacement") -> Longest Repeating Char Replacement | H42: 25–35 min
C43: 1004 | D43: LC | E43: Medium | F43: ☐ | G43: =HYPERLINK("https://leetcode.com/problems/max-consecutive-ones-iii/","Max Consecutive Ones III") -> Max Consecutive Ones III | H43: 25–35 min
C44: 76 | D44: LC | E44: Hard | F44: ☐ | G44: =HYPERLINK("https://leetcode.com/problems/minimum-window-substring/","Minimum Window Substring") -> Minimum Window Substring | H44: 40–55 min
C45: 239 | D45: LC | E45: Hard | F45: ☐ | G45: =HYPERLINK("https://leetcode.com/problems/sliding-window-maximum/","Sliding Window Maximum") -> Sliding Window Maximum | H45: 40–55 min
A47: 📅 🗓️ Buffer Day 1 — Revision — Re-attempt all 'Need Review' problems. Target: no hints, within 30 min each.
...

Sheet 📊 Dashboard
B1: 📊 Progress Dashboard — Update Status in '📋 Problem List' and this auto-refreshes
B3: 📈 Overall Progress
B4: Total Problems | C4: 37
B5: ✅ Done | C5: =COUNTIF('📋 Problem List'!H3:H39,"Done") -> 5
B6: 🔄 In Progress | C6: =COUNTIF('📋 Problem List'!H3:H39,"In Progress") -> 0
B7: 🔁 Need Review | C7: =COUNTIF('📋 Problem List'!H3:H39,"Need Review") -> 0
B8: 📌 To Do | C8: =COUNTIF('📋 Problem List'!H3:H39,"To Do") -> 32
B9: 🎯 Completion % | C9: =C5/37 -> 0.13513514
B11: 🎯 Difficulty Breakdown
B12: Difficulty | C12: Total | D12: Done | E12: % Done
B13: 🟢 Easy | C13: 11 | D13: =COUNTIFS('📋 Problem List'!H3:H39,"Done",'📋 Problem List'!F3:F39,"Easy") -> 4 | E13: =IF(C13=0,0,D13/C13) -> 0.36363636
B14: 🟡 Medium | C14: 23 | D14: =COUNTIFS('📋 Problem List'!H3:H39,"Done",'📋 Problem List'!F3:F39,"Medium") -> 1 | E14: =IF(C14=0,0,D14/C14) -> 0.043478261
B15: 🔴 Hard | C15: 3 | D15: =COUNTIFS('📋 Problem List'!H3:H39,"Done",'📋 Problem List'!F3:F39,"Hard") -> 0 | E15: =IF(C15=0,0,D15/C15) -> 0
B17: 📚 Topic Breakdown
B18: Topic | C18: Total | D18: Done | E18: % Done
B19: 👆 Two Pointers | C19: 14 | D19: =COUNTIFS('📋 Problem List'!H3:H39,"Done",'📋 Problem List'!D3:D39,"Two Pointers") -> 5 | E19: =IF(C19=0,0,D19/C19) -> 0.35714286
B20: ➕ Prefix Sum | C20: 10 | D20: =COUNTIFS('📋 Problem List'!H3:H39,"Done",'📋 Problem List'!D3:D39,"Prefix Sum") -> 0 | E20: =IF(C20=0,0,D20/C20) -> 0
B21: 🪟 Sliding Window | C21: 13 | D21: =COUNTIFS('📋 Problem List'!H3:H39,"Done",'📋 Problem List'!D3:D39,"Sliding Window") -> 0 | E21: =IF(C21=0,0,D21/C21) -> 0
B23: 📅 Day-wise Progress
B24: Day | C24: Focus | D24: Total | E24: Done
B25: Day 1 | C25: TP Basics | D25: 5 | E25: =COUNTIFS('📋 Problem List'!H3:H39,"Done",'📋 Problem List'!G3:G39,1) -> 5
B26: Day 2 | C26: TP Classic | D26: 5 | E26: =COUNTIFS('📋 Problem List'!H3:H39,"Done",'📋 Problem List'!G3:G39,2) -> 0
B27: Day 3 | C27: TP Hard | D27: 4 | E27: =COUNTIFS('📋 Problem List'!H3:H39,"Done",'📋 Problem List'!G3:G39,3) -> 0
B28: Day 4 | C28: Prefix Basics | D28: 5 | E28: =COUNTIFS('📋 Problem List'!H3:H39,"Done",'📋 Problem List'!G3:G39,4) -> 0
B29: Day 5 | C29: Prefix Advanced | D29: 5 | E29: =COUNTIFS('📋 Problem List'!H3:H39,"Done",'📋 Problem List'!G3:G39,5) -> 0
B30: Day 6 | C30: SW Fixed+Dynamic | D30: 6 | E30: =COUNTIFS('📋 Problem List'!H3:H39,"Done",'📋 Problem List'!G3:G39,6) -> 0
B31: Day 7 | C31: SW Hard | D31: 7 | E31: =COUNTIFS('📋 Problem List'!H3:H39,"Done",'📋 Problem List'!G3:G39,7) -> 0

Sheet 🧩 Templates
B1: 🧩 Code Templates & Patterns — Python | Two Pointers · Sliding Window · Prefix Sum
B3: 👆 TWO POINTERS — Opposite Ends (Sorted Array)
B4: def two_pointer_opposite(arr, target): left, right = 0, len(arr) - 1 result = [] while left < right: s = arr[left] + arr[right] if s == target: result.append((arr[left], arr[right])) left += 1; right -= 1 # skip duplicates while left < right and arr[left] == arr[left-1]: left += 1 while left < right and arr[right] == arr[right+1]: right -= 1 elif s < target: left += 1 else: right -= 1 return result | C4: WHEN: sorted array, find pairs/triplets summing to target PROBLEMS: Two Sum II (167), 3Sum (15), 4Sum (18), Container With Most Water (11) TIME: O(n log n) sort + O(n²) scan SPACE: O(1)
B6: 👆 TWO POINTERS — Same Direction (Write Pointer)
B7: def remove_in_place(arr, condition): write = 0 # write-pointer: next valid position for read in range(len(arr)): if condition(arr[read]): # keep this element arr[write] = arr[read] write += 1 return write # new logical length | C7: WHEN: remove/filter elements in-place from array PROBLEMS: Remove Duplicates (26), Move Zeroes (283), Remove Element (27) TIME: O(n) SPACE: O(1)
B9: 👆 TWO POINTERS — Fast & Slow (Floyd's Cycle)
B10: def has_cycle(head): slow = fast = head while fast and fast.next: slow = slow.next fast = fast.next.next if slow == fast: return True # cycle detected return False # --- Find cycle start --- def cycle_start(head): slow = fast = head while fast and fast.next: slow = slow.next; fast = fast.next.next if slow == fast: slow = head # reset one pointer to head while slow != fast: slow = slow.next; fast = fast.next return slow # meeting point = cycle start return None | C10: WHEN: cycle detection in Linked List, find middle of list PROBLEMS: Linked List Cycle (141), Cycle Start (142), Middle of LL (876) TIME: O(n) SPACE: O(1)
B12: 🪟 SLIDING WINDOW — Fixed Size k
B13: def fixed_window(arr, k): if len(arr) < k: return 0 # Build initial window window = sum(arr[:k]) best = window # Slide: add right element, drop left element for right in range(k, len(arr)): window += arr[right] - arr[right - k] best = max(best, window) # or min / append to list return best | C13: WHEN: fixed window size k, aggregate (sum/count/max) PROBLEMS: Max Sum Subarray Size K, Maximum Average Subarray I (643) TIME: O(n) SPACE: O(1)
B15: 🪟 SLIDING WINDOW — Dynamic (Expand & Contract)
B16: def dynamic_window(s): from collections import defaultdict freq = defaultdict(int) left = 0 best = 0 for right in range(len(s)): freq[s[right]] += 1 # expand right while not valid(freq): # ← define your condition freq[s[left]] -= 1 if freq[s[left]] == 0: del freq[s[left]] left += 1 # contract left best = max(best, right - left + 1) return best # Common validity checks: # longest with no repeat → len(freq) == right-left+1 # at most k distinct chars → len(freq) <= k # min subarray sum >= target→ curr_sum >= target (shrink to minimize) | C16: WHEN: longest/shortest subarray with constraint PROBLEMS: Longest Substring No Repeat (3), Fruit Into Baskets (904), Min Size Subarray Sum (209) TIME: O(n) SPACE: O(k) where k = window constraint
B18: 🪟 SLIDING WINDOW — Fixed + Frequency Map (Anagram)
B19: def find_anagrams(s, p): from collections import Counter need = Counter(p) # target frequency window = Counter() k = len(p) result = [] for right in range(len(s)): window[s[right]] += 1 # expand if right >= k: # remove outgoing char out = s[right - k] window[out] -= 1 if window[out] == 0: del window[out] if window == need: # full match result.append(right - k + 1) # window start index return result | C19: WHEN: find all anagrams / permutations of pattern in string PROBLEMS: Permutation in String (567), Find All Anagrams (438) TIME: O(n) SPACE: O(1) since alphabet is fixed
B21: 🪟 SLIDING WINDOW — Maximum via Monotonic Deque
B22: from collections import deque def sliding_max(nums, k): dq = deque() # stores INDICES, decreasing values result = [] for i, num in enumerate(nums): # remove indices outside window while dq and dq[0] <= i - k: dq.popleft() # remove smaller elements from back (monotonic decreasing) while dq and nums[dq[-1]] < num: dq.pop() dq.append(i) if i >= k - 1: # window is full result.append(nums[dq[0]]) # front = max return result | C22: WHEN: max/min in every window of size k PROBLEMS: Sliding Window Maximum (239) TIME: O(n) SPACE: O(k) ← each element enters/leaves deque once
B24: ➕ PREFIX SUM — 1D Array + Range Query
B25: def build_prefix(nums): n = len(nums) prefix = [0] * (n + 1) # prefix[0] = 0 (sentinel) for i in range(n): prefix[i + 1] = prefix[i] + nums[i] return prefix # Range sum [l, r] (0-indexed, inclusive) def range_sum(prefix, l, r): return prefix[r + 1] - prefix[l] # ── Count subarrays with sum == k ── def subarray_sum_k(nums, k): from collections import defaultdict seen = defaultdict(int) seen[0] = 1 # empty prefix curr = 0 count = 0 for num in nums: curr += num count += seen[curr - k] # how many prefixes sum to curr-k seen[curr] += 1 return count | C25: WHEN: repeated range queries; count subarrays summing to k PROBLEMS: Range Sum Query (303), Subarray Sum = K (560), Running Sum (1480) TIME: O(n) build + O(1) query SPACE: O(n)
B27: ➕ PREFIX SUM — Modulo Trick (Divisibility)
B28: # KEY INSIGHT: # (prefix[j] - prefix[i]) % k == 0 # ⟺ prefix[j] % k == prefix[i] % k # # So: count pairs of indices with same prefix_mod value def subarrays_div_k(nums, k): from collections import defaultdict count = defaultdict(int) count[0] = 1 # empty prefix prefix_mod = 0 result = 0 for num in nums: prefix_mod = (prefix_mod + num % k + k) % k # +k handles negatives result += count[prefix_mod] count[prefix_mod] += 1 return result | C28: WHEN: subarray sum divisible by k; subarray with sum multiple of k PROBLEMS: Subarray Sums Divisible by K (974), Continuous Subarray Sum (523) TIME: O(n) SPACE: O(k)
B30: ➕ PREFIX SUM — 2D Matrix (Region Queries)
B31: def build_2d_prefix(matrix): m, n = len(matrix), len(matrix[0]) dp = [[0] * (n + 1) for _ in range(m + 1)] for i in range(1, m + 1): for j in range(1, n + 1): dp[i][j] = (matrix[i-1][j-1] + dp[i-1][j] + dp[i][j-1] - dp[i-1][j-1]) # inclusion-exclusion return dp # Sum of region (r1,c1)→(r2,c2) (0-indexed) def region_sum(dp, r1, c1, r2, c2): return (dp[r2+1][c2+1] - dp[r1][c2+1] - dp[r2+1][c1] + dp[r1][c1]) | C31: WHEN: sum of any sub-matrix in O(1) after O(mn) build PROBLEMS: Matrix Block Sum (1314), Range Sum Query 2D (304) TIME: O(mn) build + O(1) query SPACE: O(mn)
B33: ➕ PREFIX SUM — Difference Array (Range Updates)
B34: def apply_range_updates(n, updates): # updates = [(l, r, val), ...] → add val to each index in [l,r] diff = [0] * (n + 1) for l, r, val in updates: diff[l] += val diff[r + 1] -= val # cancel after r # Reconstruct result via prefix sum of diff result, curr = [], 0 for i in range(n): curr += diff[i] result.append(curr) return result | C34: WHEN: multiple range-add operations → reconstruct final array PROBLEMS: Range Addition (370) TIME: O(n + q) SPACE: O(n) q = number of updates

Sheet 📝 Interview Notes
B1: 📝 Interview Quick-Reference — Pattern Signals · Tips · Company Frequency
B3: 🧠 PATTERN RECOGNITION SIGNALS
B4: Two Pointers → | C4: Sorted array + find pair/triplet with sum → Opposite ends In-place remove/filter elements → Same direction (write pointer) Linked List cycle / find middle → Fast & Slow Squeeze to maximize/minimize (area, boats) → Opposite ends K-way merge, Dutch national flag → 3-pointer variant
B5: Sliding Window → | C5: Exact window size k + aggregate (sum, max) → Fixed window Longest subarray/substring with constraint → Dynamic expand/contract Find all anagrams / permutations of pattern → Fixed + freq map Maximum / minimum in every window → Monotonic Deque (O(n)) Keywords: 'at most k', 'longest', 'minimum length', 'contiguous'
B6: Prefix Sum → | C6: Range sum queries on static array → 1D prefix array Count subarrays with sum = k (can be -ve) → Prefix + HashMap Subarray sum divisible by k → Prefix + Mod + HashMap Bulk range updates then reconstruct → Difference array 2D region sum queries → 2D prefix (inclusion-exclusion)
B8: ⚡ INTERVIEW EXECUTION TIPS
B9: Before you code | C9: 1. Ask: is array sorted? can there be duplicates? negative numbers? 2. Can I modify input in place? What should I return? 3. State the brute-force first, then optimize. 4. Declare time/space complexity before you start typing.
B10: While coding | C10: 1. Name pointers clearly: left/right, slow/fast, write/read. 2. Edge cases: empty input, k > n, single element, all same. 3. Check for integer overflow (use // in Python, long in Java). 4. Dry-run your code on the example before submitting.
B11: Common Traps | C11: • 3Sum / 4Sum: must skip duplicates after placing each element. • Sliding window: off-by-one → window size = right - left + 1. • Prefix mod with negatives: use (mod + k) % k to stay positive. • Anagram window: delete key from dict when count hits 0, not just decrement. • 2D prefix: use 1-indexed dp to avoid boundary checks.
B13: 🏢 COMPANY FREQUENCY (SDE-2 Level)
B14: Google / Meta | C14: ⭐⭐⭐ Minimum Window Substring (76) ⭐⭐⭐ Trapping Rain Water (42) ⭐⭐⭐ Sliding Window Maximum (239) ⭐⭐ Subarray Sum = K (560) ⭐⭐ 3Sum (15) + Longest Substr No Repeat (3)
B15: Amazon / Microsoft | C15: ⭐⭐⭐ Product of Array Except Self (238) ⭐⭐⭐ Container With Most Water (11) ⭐⭐ Longest Repeating Char Replacement (424) ⭐⭐ Minimum Size Subarray Sum (209) ⭐ Find All Anagrams (438)
B16: Flipkart / Swiggy / Zomato / Meesho | C16: ⭐⭐⭐ Permutation in String (567) ⭐⭐ Continuous Subarray Sum (523) ⭐⭐ Max Consecutive Ones III (1004) ⭐⭐ Subarray Sums Divisible by K (974) ⭐ Partition Labels (763)
B18: 📋 COMPLEXITY CHEATSHEET
B19: Two Pointers | C19: Opposite ends (one pass): O(n) time O(1) space 3Sum (sort + two ptr): O(n²) time O(1) space Fast/Slow pointer: O(n) time O(1) space
B20: Sliding Window | C20: Fixed window: O(n) time O(1) space Dynamic window (char freq): O(n) time O(k) space Monotonic Deque: O(n) time O(k) space
B21: Prefix Sum | C21: Build prefix array: O(n) time O(n) space Range query after build: O(1) time O(1) space Prefix + HashMap (count k): O(n) time O(n) space 2D prefix build: O(mn) time O(mn) space Difference array: O(n+q) time O(n) space
